Workbook

Sheet Overview
A1: Healthcare Appointment No-Show Analysis · Chi-Square Tests
A2: Statistical tests behind the hypothesis tree · Medical Appointment No-Shows (Kaggle) · Vitória, Brazil · April 29 – June 8, 2016
A4: Valid appointments | B4: No-shows | C4: Overall no-show rate
A5: ='H1.1_Lead_Time'!D13 -> 110521 | B5: ='H1.1_Lead_Time'!C13 -> 22314 | C5: ='H1.1_Lead_Time'!E13 -> 0.20189828
A7: Central question: how can we reduce no-shows to medical appointments?
A8: Each hypothesis has its own sheet with observed and expected counts, contributions, test summary, verdict and reading. Click a sheet name to open it. See "Method" for why chi-square was used and how verdicts were decided.
A10: Sheet | B10: Hypothesis | C10: Test | D10: Key result | E10: Verdict
A11: H1 · Scheduling process
A12: H1.1_Lead_Time | B12: Longer lead time → more no-shows | C12: Chi-square 6 × 2 (5 d.f.) | D12: ='H1.1_Lead_Time'!B22 -> 28.355443 | E12: ='H1.1_Lead_Time'!B23 -> Confirmed
A13: H1.2_Weekday | B13: Rate varies by weekday | C13: Chi-square 5 × 2 (4 d.f.) | D13: ='H1.2_Weekday'!B21 -> 1.8767279 | E13: ='H1.2_Weekday'!B22 -> Rejected
A14: H1.3_Concentration | B14: One or two lead-time groups hold > 50% of no-shows | C14: Distribution (no test) | D14: ="Top 2 = "&TEXT('H1.3_Concentration'!B17,"0.0%")&" · 1+ days = "&TEXT('H1.3_Concentration'!B18,"0%")&" of no-shows" -> Top 2 = 43% · 1+ days = 92% of no-shows | E14: ='H1.3_Concentration'!B21 -> Rejected
A15: H2 · Communication
A16: H2.1_SMS_Raw | B16: SMS vs no SMS, raw | C16: Chi-square 2 × 2 (1 d.f.) | D16: ='H2.1_SMS_Raw'!B18 -> 10.876561 | E16: ='H2.1_SMS_Raw'!B19 -> Inconclusive (confounded)
A17: H2.2_SMS_Controlled | B17: SMS effect within the same lead-time group | C17: Chi-square 2 × 2 per group | D17: −3.1 to −7.3 p.p. in groups of 4+ days | E17: ='H2.2_SMS_Controlled'!B20 -> Confirmed
A18: H3 · Patient characteristics
A19: H3.1_Age | B19: Rate varies by age group | C19: Chi-square 5 × 2 (4 d.f.) | D19: ='H3.1_Age'!B21 -> 10.646815 | E19: ='H3.1_Age'!B22 -> Confirmed
A20: H3.1_Gender | B20: Rate differs between women and men | C20: Chi-square 2 × 2 (1 d.f.) | D20: ='H3.1_Gender'!B18 -> -0.3477327 | E20: ='H3.1_Gender'!B19 -> Rejected
A21: H3.2_Scholarship | B21: Scholarship beneficiaries differ | C21: Chi-square 2 × 2 (1 d.f.) | D21: ='H3.2_Scholarship'!B18 -> 3.9329729 | E21: ='H3.2_Scholarship'!B19 -> Confirmed (weak)
A22: H3.3_Hypertension | B22: Hypertension | C22: Chi-square 2 × 2 (1 d.f.) | D22: ='H3.3_Hypertension'!B18 -> -3.5975003 | E22: ='H3.3_Hypertension'!B19 -> Confirmed (weak)
A23: H3.3_Diabetes | B23: Diabetes | C23: Chi-square 2 × 2 (1 d.f.) | D23: ='H3.3_Diabetes'!B18 -> -2.355868 | E23: ='H3.3_Diabetes'!B19 -> Rejected
A24: H3.3_Alcoholism | B24: Alcoholism | C24: Chi-square 2 × 2 (1 d.f.) | D24: ='H3.3_Alcoholism'!B18 -> -0.042304781 | E24: ='H3.3_Alcoholism'!B19 -> Rejected
A25: H3.3_Disability | B25: Disability | C25: Chi-square 2 × 2 (1 d.f.) | D25: ='H3.3_Disability'!B18 -> -2.1448474 | E25: ='H3.3_Disability'!B19 -> Rejected
A26: H3.4_History | B26: Prior no-show → more no-shows | C26: Chi-square 3 × 2 (2 d.f.) | D26: ='H3.4_History'!B19 -> 8.0254584 | E26: ='H3.4_History'!B20 -> Confirmed
A27: H4 · Geographic context
A28: H4.1_Neighborhoods | B28: Some neighborhoods ≥ 3 p.p. above average | C28: Chi-square 69 × 2 (68 d.f.) | D28: ='H4.1_Neighborhoods'!B85&" neighborhoods · "&TEXT('H4.1_Neighborhoods'!B86,"0.0%")&" of appts, "&TEXT('H4.1_Neighborhoods'!B87,"0.0%")&" of no-shows" -> 6 neighborhoods · 10% of appts, 13% of no-shows | E28: ='H4.1_Neighborhoods'!B90 -> Confirmed (limited impact)
A29: H4.2_Neighborhoods_Ctrl | B29: Gap persists within lead-time groups | C29: Rate comparison per group | D29: =TEXT(MIN('H4.2_Neighborhoods_Ctrl'!H7:H12),"+0.0")&" to "&TEXT(MAX('H4.2_Neighborhoods_Ctrl'!H7:H12),"+0.0")&" p.p. in every group" -> +01 to +12 p.p. in every group | E29: ='H4.2_Neighborhoods_Ctrl'!B20 -> Confirmed
A31: Built in Excel from pivot tables on the cleaned dataset. Blue numbers are inputs; all other values are formulas.
A32: Method and glossary →

Sheet Method
A1: Method and glossary | C1: ← Back to Overview
A3: Why the chi-square test
A4: Categorical outcome | B4: No-show (Yes/No) is a proportion, not an average, so t-tests do not apply.
A5: Categorical predictors | B5: Lead-time group, SMS, age group, neighborhood... One test covers all groups at once.
A6: Assumptions | B6: Expected count ≥ 5 per cell. Small groups were excluded (Saturday, neighborhoods < 200 appointments). Some patients have several appointments, so observations are not fully independent.
A7: Transparent | B7: Compares observed counts with the counts expected if there were no relationship: E = row total × column total ÷ grand total.
A9: Decision rule
A10: Confirmed | B10: p < 0.05 AND rate difference ≥ criterion (5 p.p. for lead time, 3 p.p. otherwise).
A11: Confirmed (weak) | B11: Confirmed, but Cramér's V < 0.05: the effect exists but explains little of the variation.
A12: Rejected | B12: p ≥ 0.05, or the difference is below the criterion (statistically significant but too small to matter).
A13: Inconclusive | B13: The comparison is confounded by another variable (raw SMS comparison, H2.1).
A15: Measures
A16: Chi-square (χ²) | B16: Sum of (Observed − Expected)² ÷ Expected. The larger, the further the data are from "no relationship".
A17: Degrees of freedom | B17: (rows − 1) × (columns − 1). Sets the critical value (3.84 for 1 d.f., 11.07 for 5 d.f.).
A18: p-value | B18: Probability of a difference this large if there were no relationship. With 110,000 rows almost everything is < 0.05.
A19: Cramér's V | B19: Strength of association from 0 to 1, independent of sample size. √(χ² ÷ N) for tables with two columns.
A20: Rate difference | B20: Highest rate minus lowest rate (or group B minus group A) in percentage points. p.p. is not %.
A22: Limitations
A23: Association, not causation | B23: Observational data. Only a controlled pilot (A/B test) can prove the effect of an action.
A24: Repeated patients | B24: Some patients have several appointments, which partly violates independence: p-values are slightly optimistic.
A25: Confounding | B25: The test compares two variables at a time. Stratified tests (H2.2, H4.2) were used where a confounder was likely.
A26: Before/after designs | B26: Measuring the same patients twice needs McNemar's test, not chi-square.
A27: Period | B27: April 29 to June 8, 2016 only (about six weeks); no-show history is truncated at the start of the period.
A29: Colour legend
A30: Blue numbers | B30: Observed counts taken from pivot tables on the cleaned dataset (110,521 appointments). These are the inputs.
A31: Black numbers | B31: Calculated with formulas. Changing an input updates the whole test.

Sheet H1.1_Lead_Time
A1: H1.1 · Lead time | L1: ← Back to Overview
A2: Hypothesis: Appointments booked further in advance have a higher no-show rate.
A3: Chi-square test of independence · Observed counts (blue) come from pivot tables on the cleaned dataset; everything else is calculated.
A5: Observed | G5: Expected (if no relationship) | J5: Contribution (O − E)² / E
A6: Lead time group | B6: No | C6: Yes | D6: Total | E6: No-show rate | G6: Expected No | H6: Expected Yes | J6: Contribution No | K6: Contribution Yes
A7: Same day | B7: 36770 | C7: 1792 | D7: =B7+C7 -> 38562 | E7: =C7/D7 -> 0.046470619 | G7: =$D7*B$13/$D$13 -> 30776.398 | H7: =$D7*C$13/$D$13 -> 7785.6015 | J7: =(B7-G7)^2/G7 -> 1167.234 | K7: =(C7-H7)^2/H7 -> 4614.0634
A8: 1–3 days | B8: 11316 | C8: 3359 | D8: =B8+C8 -> 14675 | E8: =C8/D8 -> 0.22889267 | G8: =$D8*B$13/$D$13 -> 11712.143 | H8: =$D8*C$13/$D$13 -> 2962.8573 | J8: =(B8-G8)^2/G8 -> 13.398834 | K8: =(C8-H8)^2/H8 -> 52.965444
A9: 4–7 days | B9: 13097 | C9: 4413 | D9: =B9+C9 -> 17510 | E9: =C9/D9 -> 0.25202741 | G9: =$D9*B$13/$D$13 -> 13974.761 | H9: =$D9*C$13/$D$13 -> 3535.2389 | J9: =(B9-G9)^2/G9 -> 55.132572 | K9: =(C9-H9)^2/H9 -> 217.93846
A10: 8–15 days | B10: 9362 | C10: 4166 | D10: =B10+C10 -> 13528 | E10: =C10/D10 -> 0.30795387 | G10: =$D10*B$13/$D$13 -> 10796.72 | H10: =$D10*C$13/$D$13 -> 2731.28 | J10: =(B10-G10)^2/G10 -> 190.65249 | K10: =(C10-H10)^2/H10 -> 753.64724
A11: 16–30 days | B11: 10709 | C11: 5159 | D11: =B11+C11 -> 15868 | E11: =C11/D11 -> 0.32511974 | G11: =$D11*B$13/$D$13 -> 12664.278 | H11: =$D11*C$13/$D$13 -> 3203.7219 | J11: =(B11-G11)^2/G11 -> 301.88158 | K11: =(C11-H11)^2/H11 -> 1193.3346
A12: 31+ days | B12: 6953 | C12: 3425 | D12: =B12+C12 -> 10378 | E12: =C12/D12 -> 0.33002505 | G12: =$D12*B$13/$D$13 -> 8282.6996 | H12: =$D12*C$13/$D$13 -> 2095.3004 | J12: =(B12-G12)^2/G12 -> 213.46918 | K12: =(C12-H12)^2/H12 -> 843.84136
A13: Total | B13: =SUM(B7:B12) -> 88207 | C13: =SUM(C7:C12) -> 22314 | D13: =SUM(D7:D12) -> 110521 | E13: =C13/D13 -> 0.20189828 | G13: =SUM(G7:G12) -> 88207 | H13: =SUM(H7:H12) -> 22314 | J13: =SUM(J7:J12) -> 1941.7687 | K13: =SUM(K7:K12) -> 7675.7906
A15: Test summary
A16: Measure | B16: Value | C16: Criterion | D16: Met?
A17: Chi-square (χ²) | B17: =SUM(J7:K12) -> 9617.5593 | C17: > critical value | D17: =IF(B17>B19,"Yes","No") -> Yes
A18: Degrees of freedom | B18: =(6-1)*(2-1) -> 5 | C18: (r − 1)(c − 1) | D18: —
A19: Critical value (α = 0.05) | B19: =CHIINV(0.05,B18) -> 11.070498 | D19: —
A20: p-value | B20: =CHITEST(B7:C12,G7:H12) -> 0 | C20: < 0.05 | D20: =IF(B20<0.05,"Yes","No") -> Yes
A21: Cramér's V | B21: =SQRT(B17/D13) -> 0.29499186 | C21: see Method | D21: —
A22: Rate difference | B22: =(MAX(E7:E12)-MIN(E7:E12))*100 -> 28.355443 | C22: 5 | D22: =IF(ABS(B22)>=C22,"Yes","No") -> Yes
A23: Verdict | B23: =IF(AND(B20<0.05,D22="Yes"),IF(B21<0.05,"Confirmed (weak)","Confirmed"),"Rejected") -> Confirmed
A25: Reading
A26: The no-show rate rises in every group, from 4.6% (same day) to 33.0% (31+ days). The biggest jump is between same day and 1–3 days. Lead time = days between the booking date and the appointment date. Association, not causation: same-day appointments may be walk-ins or urgent cases.

Sheet H1.2_Weekday
A1: H1.2 · Day of the week | L1: ← Back to Overview
A2: Hypothesis: The no-show rate varies by weekday.
A3: Chi-square test of independence · Observed counts (blue) come from pivot tables on the cleaned dataset; everything else is calculated.
A5: Observed | G5: Expected (if no relationship) | J5: Contribution (O − E)² / E
A6: Weekday | B6: No | C6: Yes | D6: Total | E6: No-show rate | G6: Expected No | H6: Expected Yes | J6: Contribution No | K6: Contribution Yes
A7: Monday | B7: 18024 | C7: 4689 | D7: =B7+C7 -> 22713 | E7: =C7/D7 -> 0.20644565 | G7: =$D7*B$12/$D$12 -> 18127.516 | H7: =$D7*C$12/$D$12 -> 4585.4842 | J7: =(B7-G7)^2/G7 -> 0.59111914 | K7: =(C7-H7)^2/H7 -> 2.3368354
A8: Tuesday | B8: 20488 | C8: 5150 | D8: =B8+C8 -> 25638 | E8: =C8/D8 -> 0.2008737 | G8: =$D8*B$12/$D$12 -> 20461.993 | H8: =$D8*C$12/$D$12 -> 5176.0069 | J8: =(B8-G8)^2/G8 -> 0.033054298 | K8: =(C8-H8)^2/H8 -> 0.13067154
A9: Wednesday | B9: 20774 | C9: 5092 | D9: =B9+C9 -> 25866 | E9: =C9/D9 -> 0.19686074 | G9: =$D9*B$12/$D$12 -> 20643.963 | H9: =$D9*C$12/$D$12 -> 5222.0373 | J9: =(B9-G9)^2/G9 -> 0.81911169 | K9: =(C9-H9)^2/H9 -> 3.2381444
A10: Thursday | B10: 13909 | C10: 3337 | D10: =B10+C10 -> 17246 | E10: =C10/D10 -> 0.19349414 | G10: =$D10*B$12/$D$12 -> 13764.238 | H10: =$D10*C$12/$D$12 -> 3481.762 | J10: =(B10-G10)^2/G10 -> 1.522499 | K10: =(C10-H10)^2/H10 -> 6.0188027
A11: Friday | B11: 14982 | C11: 4037 | D11: =B11+C11 -> 19019 | E11: =C11/D11 -> 0.21226142 | G11: =$D11*B$12/$D$12 -> 15179.29 | H11: =$D11*C$12/$D$12 -> 3839.7096 | J11: =(B11-G11)^2/G11 -> 2.5642507 | K11: =(C11-H11)^2/H11 -> 10.137096
A12: Total | B12: =SUM(B7:B11) -> 88177 | C12: =SUM(C7:C11) -> 22305 | D12: =SUM(D7:D11) -> 110482 | E12: =C12/D12 -> 0.20188809 | G12: =SUM(G7:G11) -> 88177 | H12: =SUM(H7:H11) -> 22305 | J12: =SUM(J7:J11) -> 5.5300348 | K12: =SUM(K7:K11) -> 21.86155
A14: Test summary
A15: Measure | B15: Value | C15: Criterion | D15: Met?
A16: Chi-square (χ²) | B16: =SUM(J7:K11) -> 27.391585 | C16: > critical value | D16: =IF(B16>B18,"Yes","No") -> Yes
A17: Degrees of freedom | B17: =(5-1)*(2-1) -> 4 | C17: (r − 1)(c − 1) | D17: —
A18: Critical value (α = 0.05) | B18: =CHIINV(0.05,B17) -> 9.487729 | D18: —
A19: p-value | B19: =CHITEST(B7:C11,G7:H11) -> 1.6564788e-05 | C19: < 0.05 | D19: =IF(B19<0.05,"Yes","No") -> Yes
A20: Cramér's V | B20: =SQRT(B16/D12) -> 0.015745731 | C20: see Method | D20: —
A21: Rate difference | B21: =(MAX(E7:E11)-MIN(E7:E11))*100 -> 1.8767279 | C21: 3 | D21: =IF(ABS(B21)>=C21,"Yes","No") -> No
A22: Verdict | B22: =IF(AND(B19<0.05,D21="Yes"),IF(B20<0.05,"Confirmed (weak)","Confirmed"),"Rejected") -> Rejected
A24: Reading
A25: Statistically significant only because of the large sample: the rate stays between 19.3% (Thursday) and 21.2% (Friday), and Cramér's V is negligible. Saturday was excluded (39 appointments, unstable rate). No weekday-specific action is justified.

Sheet H1.3_Concentration
A1: H1.3 · Concentration of no-shows | L1: ← Back to Overview
A2: Hypothesis: One or two lead-time groups account for more than 50% of all no-shows.
A3: Distribution analysis (no statistical test) · Uses the observed counts of H1.1
A5: Share of appointments vs share of no-shows
A6: Lead time group | B6: Share of appointments | C6: Share of no-shows | D6: Concentration index
A7: ='H1.1_Lead_Time'!A7 -> Same day | B7: ='H1.1_Lead_Time'!D7/'H1.1_Lead_Time'!D13 -> 0.34891107 | C7: ='H1.1_Lead_Time'!C7/'H1.1_Lead_Time'!C13 -> 0.080308327 | D7: =C7/B7 -> 0.23016847
A8: ='H1.1_Lead_Time'!A8 -> 1–3 days | B8: ='H1.1_Lead_Time'!D8/'H1.1_Lead_Time'!D13 -> 0.1327802 | C8: ='H1.1_Lead_Time'!C8/'H1.1_Lead_Time'!C13 -> 0.1505333 | D8: =C8/B8 -> 1.1337029
A9: ='H1.1_Lead_Time'!A9 -> 4–7 days | B9: ='H1.1_Lead_Time'!D9/'H1.1_Lead_Time'!D13 -> 0.15843143 | C9: ='H1.1_Lead_Time'!C9/'H1.1_Lead_Time'!C13 -> 0.19776822 | D9: =C9/B9 -> 1.248289
A10: ='H1.1_Lead_Time'!A10 -> 8–15 days | B10: ='H1.1_Lead_Time'!D10/'H1.1_Lead_Time'!D13 -> 0.12240208 | C10: ='H1.1_Lead_Time'!C10/'H1.1_Lead_Time'!C13 -> 0.18669893 | D10: =C10/B10 -> 1.5252922
A11: ='H1.1_Lead_Time'!A11 -> 16–30 days | B11: ='H1.1_Lead_Time'!D11/'H1.1_Lead_Time'!D13 -> 0.14357452 | C11: ='H1.1_Lead_Time'!C11/'H1.1_Lead_Time'!C13 -> 0.23120014 | D11: =C11/B11 -> 1.6103145
A12: ='H1.1_Lead_Time'!A12 -> 31+ days | B12: ='H1.1_Lead_Time'!D12/'H1.1_Lead_Time'!D13 -> 0.093900707 | C12: ='H1.1_Lead_Time'!C12/'H1.1_Lead_Time'!C13 -> 0.15349108 | D12: =C12/B12 -> 1.6346105
A13: Total | B13: =SUM(B7:B12) -> 1 | C13: =SUM(C7:C12) -> 1
A15: Test summary
A16: Measure | B16: Value | C16: Criterion | D16: Met?
A17: Top two groups, share of no-shows | B17: =LARGE(C7:C12,1)+LARGE(C7:C12,2) -> 0.42896836 | C17: 0.5 | D17: =IF(B17>C17,"Yes","No") -> No
A18: Appointments booked 1+ days ahead, share of no-shows | B18: =1-C7 -> 0.91969167 | D18: —
A19: Appointments booked 1+ days ahead, share of appointments | B19: =1-B7 -> 0.65108893 | D19: —
A21: Verdict | B21: =IF(D17="Yes","Confirmed","Rejected") -> Rejected
A23: Reading
A24: No-shows are spread across the groups of 1+ days, so the 50% criterion is not met. The real divide is "same day" vs "another day": appointments booked one or more days ahead hold 65% of appointments but 92% of no-shows. The 4–7 group produces more no-shows than 31+ despite a lower rate because it has more appointments (no-shows = appointments × rate).

Sheet H2.1_SMS_Raw
A1: H2.1 · SMS reminder (raw comparison) | L1: ← Back to Overview
A2: Hypothesis: The no-show rate differs between appointments with and without an SMS.
A3: Chi-square test of independence · Observed counts (blue) come from pivot tables on the cleaned dataset; everything else is calculated.
A5: Observed | G5: Expected (if no relationship) | J5: Contribution (O − E)² / E
A6: SMS received | B6: No | C6: Yes | D6: Total | E6: No-show rate | G6: Expected No | H6: Expected Yes | J6: Contribution No | K6: Contribution Yes
A7: Without SMS | B7: 62509 | C7: 12530 | D7: =B7+C7 -> 75039 | E7: =C7/D7 -> 0.16697984 | G7: =$D7*B$9/$D$9 -> 59888.755 | H7: =$D7*C$9/$D$9 -> 15150.245 | J7: =(B7-G7)^2/G7 -> 114.64063 | K7: =(C7-H7)^2/H7 -> 453.17318
A8: With SMS | B8: 25698 | C8: 9784 | D8: =B8+C8 -> 35482 | E8: =C8/D8 -> 0.27574545 | G8: =$D8*B$9/$D$9 -> 28318.245 | H8: =$D8*C$9/$D$9 -> 7163.7548 | J8: =(B8-G8)^2/G8 -> 242.44739 | K8: =(C8-H8)^2/H8 -> 958.39192
A9: Total | B9: =SUM(B7:B8) -> 88207 | C9: =SUM(C7:C8) -> 22314 | D9: =SUM(D7:D8) -> 110521 | E9: =C9/D9 -> 0.20189828 | G9: =SUM(G7:G8) -> 88207 | H9: =SUM(H7:H8) -> 22314 | J9: =SUM(J7:J8) -> 357.08803 | K9: =SUM(K7:K8) -> 1411.5651
A11: Test summary
A12: Measure | B12: Value | C12: Criterion | D12: Met?
A13: Chi-square (χ²) | B13: =SUM(J7:K8) -> 1768.6531 | C13: > critical value | D13: =IF(B13>B15,"Yes","No") -> Yes
A14: Degrees of freedom | B14: =(2-1)*(2-1) -> 1 | C14: (r − 1)(c − 1) | D14: —
A15: Critical value (α = 0.05) | B15: =CHIINV(0.05,B14) -> 3.8414588 | D15: —
A16: p-value | B16: =CHITEST(B7:C8,G7:H8) -> 0 | C16: < 0.05 | D16: =IF(B16<0.05,"Yes","No") -> Yes
A17: Cramér's V | B17: =SQRT(B13/D9) -> 0.12650245 | C17: see Method | D17: —
A18: Rate difference | B18: =(E8-E7)*100 -> 10.876561 | C18: 3 | D18: =IF(ABS(B18)>=C18,"Yes","No") -> Yes
A19: Verdict | B19: Inconclusive (confounded)
A21: Reading
A22: In the raw data, the SMS group misses MORE (+10.9 p.p.). This is confounded by lead time: SMS is sent almost only to appointments booked 4+ days ahead, which already miss more (0% of same-day appointments receive an SMS vs ~60% of those booked 4+ days ahead). See H2.2 for the controlled comparison.

Sheet H2.2_SMS_Controlled
A1: H2.2 · SMS reminder within the same lead-time group | L1: ← Back to Overview
A2: Hypothesis: Within the same lead-time group, appointments with an SMS have a lower no-show rate.
A3: Chi-square 2 × 2 run separately in each lead-time group (stratified test) · χ² = N(ad − bc)² / [(a+b)(c+d)(a+c)(b+d)], 1 d.f.
A5: Observed counts and rates by lead-time group
A6: Lead time group | B6: No (no SMS) | C6: Yes (no SMS) | D6: No (SMS) | E6: Yes (SMS) | F6: Rate without SMS | G6: Rate with SMS | H6: Difference | I6: χ² | J6: p-value | K6: Cramér's V
A7: Same day | B7: 36770 | C7: 1792 | D7: 0 | E7: 0 | F7: =C7/(B7+C7) -> 0.046470619 | G7: =IF(D7+E7=0,"no SMS",E7/(D7+E7)) -> no SMS | H7: =IF(D7+E7=0,"—",(G7-F7)*100) -> — | I7: =IF(D7+E7=0,"—",(B7+C7+D7+E7)*(B7*E7-C7*D7)^2/((B7+C7)*(D7+E7)*(B7+D7)*(C7+E7))) -> — | J7: =IF(D7+E7=0,"—",CHIDIST(I7,1)) -> — | K7: =IF(D7+E7=0,"—",SQRT(I7/(B7+C7+D7+E7))) -> —
A8: 1–3 days | B8: 10603 | C8: 3166 | D8: 713 | E8: 193 | F8: =C8/(B8+C8) -> 0.22993681 | G8: =IF(D8+E8=0,"no SMS",E8/(D8+E8)) -> 0.21302428 | H8: =IF(D8+E8=0,"—",(G8-F8)*100) -> -1.6912532 | I8: =IF(D8+E8=0,"—",(B8+C8+D8+E8)*(B8*E8-C8*D8)^2/((B8+C8)*(D8+E8)*(B8+D8)*(C8+E8))) -> 1.3775997 | J8: =IF(D8+E8=0,"—",CHIDIST(I8,1)) -> 0.24051044 | K8: =IF(D8+E8=0,"—",SQRT(I8/(B8+C8+D8+E8))) -> 0.0096888551
A9: 4–7 days | B9: 5006 | C9: 1862 | D9: 8091 | E9: 2551 | F9: =C9/(B9+C9) -> 0.27111241 | G9: =IF(D9+E9=0,"no SMS",E9/(D9+E9)) -> 0.23971058 | H9: =IF(D9+E9=0,"—",(G9-F9)*100) -> -3.1401825 | I9: =IF(D9+E9=0,"—",(B9+C9+D9+E9)*(B9*E9-C9*D9)^2/((B9+C9)*(D9+E9)*(B9+D9)*(C9+E9))) -> 21.834523 | J9: =IF(D9+E9=0,"—",CHIDIST(I9,1)) -> 2.9720427e-06 | K9: =IF(D9+E9=0,"—",SQRT(I9/(B9+C9+D9+E9))) -> 0.035312525
A10: 8–15 days | B10: 3690 | C10: 1911 | D10: 5672 | E10: 2255 | F10: =C10/(B10+C10) -> 0.34118907 | G10: =IF(D10+E10=0,"no SMS",E10/(D10+E10)) -> 0.2844708 | H10: =IF(D10+E10=0,"—",(G10-F10)*100) -> -5.6718277 | I10: =IF(D10+E10=0,"—",(B10+C10+D10+E10)*(B10*E10-C10*D10)^2/((B10+C10)*(D10+E10)*(B10+D10)*(C10+E10))) -> 49.541162 | J10: =IF(D10+E10=0,"—",CHIDIST(I10,1)) -> 1.94253e-12 | K10: =IF(D10+E10=0,"—",SQRT(I10/(B10+C10+D10+E10))) -> 0.060515454
A11: 16–30 days | B11: 3961 | C11: 2310 | D11: 6748 | E11: 2849 | F11: =C11/(B11+C11) -> 0.3683623 | G11: =IF(D11+E11=0,"no SMS",E11/(D11+E11)) -> 0.2968636 | H11: =IF(D11+E11=0,"—",(G11-F11)*100) -> -7.1498699 | I11: =IF(D11+E11=0,"—",(B11+C11+D11+E11)*(B11*E11-C11*D11)^2/((B11+C11)*(D11+E11)*(B11+D11)*(C11+E11))) -> 88.364195 | J11: =IF(D11+E11=0,"—",CHIDIST(I11,1)) -> 5.4447481e-21 | K11: =IF(D11+E11=0,"—",SQRT(I11/(B11+C11+D11+E11))) -> 0.07462375
A12: 31+ days | B12: 2479 | C12: 1489 | D12: 4474 | E12: 1936 | F12: =C12/(B12+C12) -> 0.37525202 | G12: =IF(D12+E12=0,"no SMS",E12/(D12+E12)) -> 0.30202808 | H12: =IF(D12+E12=0,"—",(G12-F12)*100) -> -7.3223935 | I12: =IF(D12+E12=0,"—",(B12+C12+D12+E12)*(B12*E12-C12*D12)^2/((B12+C12)*(D12+E12)*(B12+D12)*(C12+E12))) -> 59.431499 | J12: =IF(D12+E12=0,"—",CHIDIST(I12,1)) -> 1.2662598e-14 | K12: =IF(D12+E12=0,"—",SQRT(I12/(B12+C12+D12+E12))) -> 0.075674839
A14: Test summary
A15: Measure | B15: Value | C15: Criterion | D15: Met?
A16: Groups where SMS lowers the rate | B16: =COUNTIF(H8:H12,"<0") -> 5 | C16: Most groups | D16: =IF(B16>=3,"Yes","No") -> Yes
A17: Groups with p < 0.05 and |diff| ≥ 3 p.p. | B17: =SUMPRODUCT((J8:J12<0.05)*(H8:H12<=-C17)) -> 4 | C17: 3 | D17: =IF(B17>=3,"Yes","No") -> Yes
A18: Largest reduction | B18: =MIN(H8:H12) -> -7.3223935 | D18: —
A20: Verdict | B20: =IF(AND(D16="Yes",D17="Yes"),"Confirmed","Rejected") -> Confirmed
A22: Reading
A23: Simpson's paradox: once lead time is held constant, the SMS group has 3.1 to 7.3 p.p. fewer no-shows in every group of 4+ days, and the effect grows with lead time. The 1–3 days difference is not significant (only 906 appointments with SMS); same-day appointments receive no SMS. Association, not causation: we do not know why ~40% of 4+ day appointments received no SMS.

Sheet H3.1_Age
A1: H3.1 · Age group | L1: ← Back to Overview
A2: Hypothesis: The no-show rate varies by age group.
A3: Chi-square test of independence · Observed counts (blue) come from pivot tables on the cleaned dataset; everything else is calculated.
A5: Observed | G5: Expected (if no relationship) | J5: Contribution (O − E)² / E
A6: Age group | B6: No | C6: Yes | D6: Total | E6: No-show rate | G6: Expected No | H6: Expected Yes | J6: Contribution No | K6: Contribution Yes
A7: Child (0–12) | B7: 16729 | C7: 4306 | D7: =B7+C7 -> 21035 | E7: =C7/D7 -> 0.20470644 | G7: =$D7*B$12/$D$12 -> 16788.07 | H7: =$D7*C$12/$D$12 -> 4246.9304 | J7: =(B7-G7)^2/G7 -> 0.20783942 | K7: =(C7-H7)^2/H7 -> 0.82158699
A8: Teen (13–19) | B8: 6941 | C8: 2433 | D8: =B8+C8 -> 9374 | E8: =C8/D8 -> 0.25954769 | G8: =$D8*B$12/$D$12 -> 7481.4055 | H8: =$D8*C$12/$D$12 -> 1892.5945 | J8: =(B8-G8)^2/G8 -> 39.035194 | K8: =(C8-H8)^2/H8 -> 154.3057
A9: Young Adult (20–39) | B9: 22190 | C9: 6678 | D9: =B9+C9 -> 28868 | E9: =C9/D9 -> 0.23132881 | G9: =$D9*B$12/$D$12 -> 23039.6 | H9: =$D9*C$12/$D$12 -> 5828.3996 | J9: =(B9-G9)^2/G9 -> 31.329573 | K9: =(C9-H9)^2/H9 -> 123.84546
A10: Adult (40–59) | B10: 24416 | C10: 5656 | D10: =B10+C10 -> 30072 | E10: =C10/D10 -> 0.18808194 | G10: =$D10*B$12/$D$12 -> 24000.515 | H10: =$D10*C$12/$D$12 -> 6071.4851 | J10: =(B10-G10)^2/G10 -> 7.1926746 | K10: =(C10-H10)^2/H10 -> 28.432565
A11: Senior (60+) | B11: 17931 | C11: 3241 | D11: =B11+C11 -> 21172 | E11: =C11/D11 -> 0.15307954 | G11: =$D11*B$12/$D$12 -> 16897.41 | H11: =$D11*C$12/$D$12 -> 4274.5904 | J11: =(B11-G11)^2/G11 -> 63.223251 | K11: =(C11-H11)^2/H11 -> 249.92082
A12: Total | B12: =SUM(B7:B11) -> 88207 | C12: =SUM(C7:C11) -> 22314 | D12: =SUM(D7:D11) -> 110521 | E12: =C12/D12 -> 0.20189828 | G12: =SUM(G7:G11) -> 88207 | H12: =SUM(H7:H11) -> 22314 | J12: =SUM(J7:J11) -> 140.98853 | K12: =SUM(K7:K11) -> 557.32613
A14: Test summary
A15: Measure | B15: Value | C15: Criterion | D15: Met?
A16: Chi-square (χ²) | B16: =SUM(J7:K11) -> 698.31467 | C16: > critical value | D16: =IF(B16>B18,"Yes","No") -> Yes
A17: Degrees of freedom | B17: =(5-1)*(2-1) -> 4 | C17: (r − 1)(c − 1) | D17: —
A18: Critical value (α = 0.05) | B18: =CHIINV(0.05,B17) -> 9.487729 | D18: —
A19: p-value | B19: =CHITEST(B7:C11,G7:H11) -> 8.0753311e-150 | C19: < 0.05 | D19: =IF(B19<0.05,"Yes","No") -> Yes
A20: Cramér's V | B20: =SQRT(B16/D12) -> 0.079488294 | C20: see Method | D20: —
A21: Rate difference | B21: =(MAX(E7:E11)-MIN(E7:E11))*100 -> 10.646815 | C21: 3 | D21: =IF(ABS(B21)>=C21,"Yes","No") -> Yes
A22: Verdict | B22: =IF(AND(B19<0.05,D21="Yes"),IF(B20<0.05,"Confirmed (weak)","Confirmed"),"Rejected") -> Confirmed
A24: Reading
A25: No-shows peak among teenagers (26.0%) and fall steadily to seniors (15.3%). Seniors account for ~45% of χ² by missing far less than expected; teenagers and young adults account for about half by missing more.

Sheet H3.1_Gender
A1: H3.1 · Gender | L1: ← Back to Overview
A2: Hypothesis: The no-show rate differs between women and men.
A3: Chi-square test of independence · Observed counts (blue) come from pivot tables on the cleaned dataset; everything else is calculated.
A5: Observed | G5: Expected (if no relationship) | J5: Contribution (O − E)² / E
A6: Gender | B6: No | C6: Yes | D6: Total | E6: No-show rate | G6: Expected No | H6: Expected Yes | J6: Contribution No | K6: Contribution Yes
A7: Female | B7: 57245 | C7: 14591 | D7: =B7+C7 -> 71836 | E7: =C7/D7 -> 0.20311543 | G7: =$D7*B$9/$D$9 -> 57332.435 | H7: =$D7*C$9/$D$9 -> 14503.565 | J7: =(B7-G7)^2/G7 -> 0.1333431 | K7: =(C7-H7)^2/H7 -> 0.52710382
A8: Male | B8: 30962 | C8: 7723 | D8: =B8+C8 -> 38685 | E8: =C8/D8 -> 0.1996381 | G8: =$D8*B$9/$D$9 -> 30874.565 | H8: =$D8*C$9/$D$9 -> 7810.435 | J8: =(B8-G8)^2/G8 -> 0.24761109 | K8: =(C8-H8)^2/H8 -> 0.97880394
A9: Total | B9: =SUM(B7:B8) -> 88207 | C9: =SUM(C7:C8) -> 22314 | D9: =SUM(D7:D8) -> 110521 | E9: =C9/D9 -> 0.20189828 | G9: =SUM(G7:G8) -> 88207 | H9: =SUM(H7:H8) -> 22314 | J9: =SUM(J7:J8) -> 0.38095418 | K9: =SUM(K7:K8) -> 1.5059078
A11: Test summary
A12: Measure | B12: Value | C12: Criterion | D12: Met?
A13: Chi-square (χ²) | B13: =SUM(J7:K8) -> 1.8868619 | C13: > critical value | D13: =IF(B13>B15,"Yes","No") -> No
A14: Degrees of freedom | B14: =(2-1)*(2-1) -> 1 | C14: (r − 1)(c − 1) | D14: —
A15: Critical value (α = 0.05) | B15: =CHIINV(0.05,B14) -> 3.8414588 | D15: —
A16: p-value | B16: =CHITEST(B7:C8,G7:H8) -> 0.16955629 | C16: < 0.05 | D16: =IF(B16<0.05,"Yes","No") -> No
A17: Cramér's V | B17: =SQRT(B13/D9) -> 0.0041318796 | C17: see Method | D17: —
A18: Rate difference | B18: =(E8-E7)*100 -> -0.3477327 | C18: 3 | D18: =IF(ABS(B18)>=C18,"Yes","No") -> No
A19: Verdict | B19: =IF(AND(B16<0.05,D18="Yes"),IF(B17<0.05,"Confirmed (weak)","Confirmed"),"Rejected") -> Rejected
A21: Reading
A22: Women book almost twice as many appointments, but once booked, women and men miss at the same rate (p = 0.17). No evidence of a difference.

Sheet H3.2_Scholarship
A1: H3.2_Scholarship (cash-transfer program) | L1: ← Back to Overview
A2: Hypothesis: Beneficiaries have a different no-show rate.
A3: Chi-square test of independence · Observed counts (blue) come from pivot tables on the cleaned dataset; everything else is calculated.
A5: Observed | G5: Expected (if no relationship) | J5: Contribution (O − E)² / E
A6: Bolsa Família | B6: No | C6: Yes | D6: Total | E6: No-show rate | G6: Expected No | H6: Expected Yes | J6: Contribution No | K6: Contribution Yes
A7: Not a beneficiary | B7: 79924 | C7: 19736 | D7: =B7+C7 -> 99660 | E7: =C7/D7 -> 0.19803331 | G7: =$D7*B$9/$D$9 -> 79538.817 | H7: =$D7*C$9/$D$9 -> 20121.183 | J7: =(B7-G7)^2/G7 -> 1.8653252 | K7: =(C7-H7)^2/H7 -> 7.3736103
A8: Beneficiary | B8: 8283 | C8: 2578 | D8: =B8+C8 -> 10861 | E8: =C8/D8 -> 0.23736304 | G8: =$D8*B$9/$D$9 -> 8668.1828 | H8: =$D8*C$9/$D$9 -> 2192.8172 | J8: =(B8-G8)^2/G8 -> 17.116132 | K8: =(C8-H8)^2/H8 -> 67.659884
A9: Total | B9: =SUM(B7:B8) -> 88207 | C9: =SUM(C7:C8) -> 22314 | D9: =SUM(D7:D8) -> 110521 | E9: =C9/D9 -> 0.20189828 | G9: =SUM(G7:G8) -> 88207 | H9: =SUM(H7:H8) -> 22314 | J9: =SUM(J7:J8) -> 18.981457 | K9: =SUM(K7:K8) -> 75.033494
A11: Test summary
A12: Measure | B12: Value | C12: Criterion | D12: Met?
A13: Chi-square (χ²) | B13: =SUM(J7:K8) -> 94.014951 | C13: > critical value | D13: =IF(B13>B15,"Yes","No") -> Yes
A14: Degrees of freedom | B14: =(2-1)*(2-1) -> 1 | C14: (r − 1)(c − 1) | D14: —
A15: Critical value (α = 0.05) | B15: =CHIINV(0.05,B14) -> 3.8414588 | D15: —
A16: p-value | B16: =CHITEST(B7:C8,G7:H8) -> 3.131495e-22 | C16: < 0.05 | D16: =IF(B16<0.05,"Yes","No") -> Yes
A17: Cramér's V | B17: =SQRT(B13/D9) -> 0.029165946 | C17: see Method | D17: —
A18: Rate difference | B18: =(E8-E7)*100 -> 3.9329729 | C18: 3 | D18: =IF(ABS(B18)>=C18,"Yes","No") -> Yes
A19: Verdict | B19: =IF(AND(B16<0.05,D18="Yes"),IF(B17<0.05,"Confirmed (weak)","Confirmed"),"Rejected") -> Confirmed (weak)
A21: Reading
A22: Beneficiaries miss 3.9 p.p. more, just above the criterion, but the association is negligible (V = 0.03) and may reflect age, neighborhood or lead time. Any action should reduce access barriers, never penalize beneficiaries.

Sheet H3.3_Hypertension
A1: H3.3 · Hypertension | L1: ← Back to Overview
A2: Hypothesis: Patients with hypertension have a different no-show rate.
A3: Chi-square test of independence · Observed counts (blue) come from pivot tables on the cleaned dataset; everything else is calculated.
A5: Observed | G5: Expected (if no relationship) | J5: Contribution (O − E)² / E
A6: Condition | B6: No | C6: Yes | D6: Total | E6: No-show rate | G6: Expected No | H6: Expected Yes | J6: Contribution No | K6: Contribution Yes
A7: Without hypertension | B7: 70178 | C7: 18542 | D7: =B7+C7 -> 88720 | E7: =C7/D7 -> 0.20899459 | G7: =$D7*B$9/$D$9 -> 70807.584 | H7: =$D7*C$9/$D$9 -> 17912.416 | J7: =(B7-G7)^2/G7 -> 5.5979394 | K7: =(C7-H7)^2/H7 -> 22.128594
A8: With hypertension | B8: 18029 | C8: 3772 | D8: =B8+C8 -> 21801 | E8: =C8/D8 -> 0.17301959 | G8: =$D8*B$9/$D$9 -> 17399.416 | H8: =$D8*C$9/$D$9 -> 4401.5844 | J8: =(B8-G8)^2/G8 -> 22.781028 | K8: =(C8-H8)^2/H8 -> 90.053156
A9: Total | B9: =SUM(B7:B8) -> 88207 | C9: =SUM(C7:C8) -> 22314 | D9: =SUM(D7:D8) -> 110521 | E9: =C9/D9 -> 0.20189828 | G9: =SUM(G7:G8) -> 88207 | H9: =SUM(H7:H8) -> 22314 | J9: =SUM(J7:J8) -> 28.378967 | K9: =SUM(K7:K8) -> 112.18175
A11: Test summary
A12: Measure | B12: Value | C12: Criterion | D12: Met?
A13: Chi-square (χ²) | B13: =SUM(J7:K8) -> 140.56072 | C13: > critical value | D13: =IF(B13>B15,"Yes","No") -> Yes
A14: Degrees of freedom | B14: =(2-1)*(2-1) -> 1 | C14: (r − 1)(c − 1) | D14: —
A15: Critical value (α = 0.05) | B15: =CHIINV(0.05,B14) -> 3.8414588 | D15: —
A16: p-value | B16: =CHITEST(B7:C8,G7:H8) -> 2.0072418e-32 | C16: < 0.05 | D16: =IF(B16<0.05,"Yes","No") -> Yes
A17: Cramér's V | B17: =SQRT(B13/D9) -> 0.035662319 | C17: see Method | D17: —
A18: Rate difference | B18: =(E8-E7)*100 -> -3.5975003 | C18: 3 | D18: =IF(ABS(B18)>=C18,"Yes","No") -> Yes
A19: Verdict | B19: =IF(AND(B16<0.05,D18="Yes"),IF(B17<0.05,"Confirmed (weak)","Confirmed"),"Rejected") -> Confirmed (weak)
A21: Reading
A22: Hypertensive patients miss 3.6 p.p. less. Part of this may be an age effect: seniors miss less and make up most hypertensive patients.

Sheet H3.3_Diabetes
A1: H3.3 · Diabetes | L1: ← Back to Overview
A2: Hypothesis: Patients with diabetes have a different no-show rate.
A3: Chi-square test of independence · Observed counts (blue) come from pivot tables on the cleaned dataset; everything else is calculated.
A5: Observed | G5: Expected (if no relationship) | J5: Contribution (O − E)² / E
A6: Condition | B6: No | C6: Yes | D6: Total | E6: No-show rate | G6: Expected No | H6: Expected Yes | J6: Contribution No | K6: Contribution Yes
A7: Without diabetes | B7: 81694 | C7: 20884 | D7: =B7+C7 -> 102578 | E7: =C7/D7 -> 0.20359141 | G7: =$D7*B$9/$D$9 -> 81867.678 | H7: =$D7*C$9/$D$9 -> 20710.322 | J7: =(B7-G7)^2/G7 -> 0.36844902 | K7: =(C7-H7)^2/H7 -> 1.456475
A8: With diabetes | B8: 6513 | C8: 1430 | D8: =B8+C8 -> 7943 | E8: =C8/D8 -> 0.18003273 | G8: =$D8*B$9/$D$9 -> 6339.3219 | H8: =$D8*C$9/$D$9 -> 1603.6781 | J8: =(B8-G8)^2/G8 -> 4.758248 | K8: =(C8-H8)^2/H8 -> 18.809303
A9: Total | B9: =SUM(B7:B8) -> 88207 | C9: =SUM(C7:C8) -> 22314 | D9: =SUM(D7:D8) -> 110521 | E9: =C9/D9 -> 0.20189828 | G9: =SUM(G7:G8) -> 88207 | H9: =SUM(H7:H8) -> 22314 | J9: =SUM(J7:J8) -> 5.126697 | K9: =SUM(K7:K8) -> 20.265778
A11: Test summary
A12: Measure | B12: Value | C12: Criterion | D12: Met?
A13: Chi-square (χ²) | B13: =SUM(J7:K8) -> 25.392475 | C13: > critical value | D13: =IF(B13>B15,"Yes","No") -> Yes
A14: Degrees of freedom | B14: =(2-1)*(2-1) -> 1 | C14: (r − 1)(c − 1) | D14: —
A15: Critical value (α = 0.05) | B15: =CHIINV(0.05,B14) -> 3.8414588 | D15: —
A16: p-value | B16: =CHITEST(B7:C8,G7:H8) -> 4.6773921e-07 | C16: < 0.05 | D16: =IF(B16<0.05,"Yes","No") -> Yes
A17: Cramér's V | B17: =SQRT(B13/D9) -> 0.015157588 | C17: see Method | D17: —
A18: Rate difference | B18: =(E8-E7)*100 -> -2.355868 | C18: 3 | D18: =IF(ABS(B18)>=C18,"Yes","No") -> No
A19: Verdict | B19: =IF(AND(B16<0.05,D18="Yes"),IF(B17<0.05,"Confirmed (weak)","Confirmed"),"Rejected") -> Rejected
A21: Reading
A22: Diabetic patients miss slightly less, but the 2.4 p.p. difference is below the criterion.

Sheet H3.3_Alcoholism
A1: H3.3 · Alcoholism | L1: ← Back to Overview
A2: Hypothesis: Patients with alcoholism have a different no-show rate.
A3: Chi-square test of independence · Observed counts (blue) come from pivot tables on the cleaned dataset; everything else is calculated.
A5: Observed | G5: Expected (if no relationship) | J5: Contribution (O − E)² / E
A6: Condition | B6: No | C6: Yes | D6: Total | E6: No-show rate | G6: Expected No | H6: Expected Yes | J6: Contribution No | K6: Contribution Yes
A7: Without alcoholism | B7: 85524 | C7: 21637 | D7: =B7+C7 -> 107161 | E7: =C7/D7 -> 0.20191114 | G7: =$D7*B$9/$D$9 -> 85525.378 | H7: =$D7*C$9/$D$9 -> 21635.622 | J7: =(B7-G7)^2/G7 -> 2.2209887e-05 | K7: =(C7-H7)^2/H7 -> 8.7795443e-05
A8: With alcoholism | B8: 2683 | C8: 677 | D8: =B8+C8 -> 3360 | E8: =C8/D8 -> 0.2014881 | G8: =$D8*B$9/$D$9 -> 2681.6218 | H8: =$D8*C$9/$D$9 -> 678.37823 | J8: =(B8-G8)^2/G8 -> 0.00070834337 | K8: =(C8-H8)^2/H8 -> 0.0028000737
A9: Total | B9: =SUM(B7:B8) -> 88207 | C9: =SUM(C7:C8) -> 22314 | D9: =SUM(D7:D8) -> 110521 | E9: =C9/D9 -> 0.20189828 | G9: =SUM(G7:G8) -> 88207 | H9: =SUM(H7:H8) -> 22314 | J9: =SUM(J7:J8) -> 0.00073055326 | K9: =SUM(K7:K8) -> 0.0028878691
A11: Test summary
A12: Measure | B12: Value | C12: Criterion | D12: Met?
A13: Chi-square (χ²) | B13: =SUM(J7:K8) -> 0.0036184224 | C13: > critical value | D13: =IF(B13>B15,"Yes","No") -> No
A14: Degrees of freedom | B14: =(2-1)*(2-1) -> 1 | C14: (r − 1)(c − 1) | D14: —
A15: Critical value (α = 0.05) | B15: =CHIINV(0.05,B14) -> 3.8414588 | D15: —
A16: p-value | B16: =CHITEST(B7:C8,G7:H8) -> 0.95203352 | C16: < 0.05 | D16: =IF(B16<0.05,"Yes","No") -> No
A17: Cramér's V | B17: =SQRT(B13/D9) -> 0.0001809411 | C17: see Method | D17: —
A18: Rate difference | B18: =(E8-E7)*100 -> -0.042304781 | C18: 3 | D18: =IF(ABS(B18)>=C18,"Yes","No") -> No
A19: Verdict | B19: =IF(AND(B16<0.05,D18="Yes"),IF(B17<0.05,"Confirmed (weak)","Confirmed"),"Rejected") -> Rejected
A21: Reading
A22: Virtually identical rates (p = 0.95). Alcoholism is likely under-reported in the records.

Sheet H3.3_Disability
A1: H3.3 · Disability | L1: ← Back to Overview
A2: Hypothesis: Patients with a disability have a different no-show rate.
A3: Chi-square test of independence · Observed counts (blue) come from pivot tables on the cleaned dataset; everything else is calculated.
A5: Observed | G5: Expected (if no relationship) | J5: Contribution (O − E)² / E
A6: Condition | B6: No | C6: Yes | D6: Total | E6: No-show rate | G6: Expected No | H6: Expected Yes | J6: Contribution No | K6: Contribution Yes
A7: Without disability | B7: 86373 | C7: 21909 | D7: =B7+C7 -> 108282 | E7: =C7/D7 -> 0.2023328 | G7: =$D7*B$9/$D$9 -> 86420.05 | H7: =$D7*C$9/$D$9 -> 21861.95 | J7: =(B7-G7)^2/G7 -> 0.025615888 | K7: =(C7-H7)^2/H7 -> 0.10125933
A8: With disability | B8: 1834 | C8: 405 | D8: =B8+C8 -> 2239 | E8: =C8/D8 -> 0.18088432 | G8: =$D8*B$9/$D$9 -> 1786.9497 | H8: =$D8*C$9/$D$9 -> 452.05025 | J8: =(B8-G8)^2/G8 -> 1.2388296 | K8: =(C8-H8)^2/H8 -> 4.8970801
A9: Total | B9: =SUM(B7:B8) -> 88207 | C9: =SUM(C7:C8) -> 22314 | D9: =SUM(D7:D8) -> 110521 | E9: =C9/D9 -> 0.20189828 | G9: =SUM(G7:G8) -> 88207 | H9: =SUM(H7:H8) -> 22314 | J9: =SUM(J7:J8) -> 1.2644455 | K9: =SUM(K7:K8) -> 4.9983394
A11: Test summary
A12: Measure | B12: Value | C12: Criterion | D12: Met?
A13: Chi-square (χ²) | B13: =SUM(J7:K8) -> 6.2627849 | C13: > critical value | D13: =IF(B13>B15,"Yes","No") -> Yes
A14: Degrees of freedom | B14: =(2-1)*(2-1) -> 1 | C14: (r − 1)(c − 1) | D14: —
A15: Critical value (α = 0.05) | B15: =CHIINV(0.05,B14) -> 3.8414588 | D15: —
A16: p-value | B16: =CHITEST(B7:C8,G7:H8) -> 0.012330023 | C16: < 0.05 | D16: =IF(B16<0.05,"Yes","No") -> Yes
A17: Cramér's V | B17: =SQRT(B13/D9) -> 0.0075276834 | C17: see Method | D17: —
A18: Rate difference | B18: =(E8-E7)*100 -> -2.1448474 | C18: 3 | D18: =IF(ABS(B18)>=C18,"Yes","No") -> No
A19: Verdict | B19: =IF(AND(B16<0.05,D18="Yes"),IF(B17<0.05,"Confirmed (weak)","Confirmed"),"Rejected") -> Rejected
A21: Reading
A22: Patients with a disability miss slightly less, but the 2.1 p.p. difference is below the criterion and p = 0.012 is close to the threshold.

Sheet H3.4_History
A1: H3.4 · No-show history | L1: ← Back to Overview
A2: Hypothesis: Patients who missed before have a higher no-show rate.
A3: Chi-square test of independence · Observed counts (blue) come from pivot tables on the cleaned dataset; everything else is calculated.
A5: Observed | G5: Expected (if no relationship) | J5: Contribution (O − E)² / E
A6: History | B6: No | C6: Yes | D6: Total | E6: No-show rate | G6: Expected No | H6: Expected Yes | J6: Contribution No | K6: Contribution Yes
A7: First visit | B7: 53444 | C7: 12844 | D7: =B7+C7 -> 66288 | E7: =C7/D7 -> 0.19376056 | G7: =$D7*B$10/$D$10 -> 52904.567 | H7: =$D7*C$10/$D$10 -> 13383.433 | J7: =(B7-G7)^2/G7 -> 5.500249 | K7: =(C7-H7)^2/H7 -> 21.742424
A8: Returning, no prior no-show | B8: 24442 | C8: 5677 | D8: =B8+C8 -> 30119 | E8: =C8/D8 -> 0.18848567 | G8: =$D8*B$10/$D$10 -> 24038.026 | H8: =$D8*C$10/$D$10 -> 6080.9743 | J8: =(B8-G8)^2/G8 -> 6.7890465 | K8: =(C8-H8)^2/H8 -> 26.837027
A9: Prior no-show | B9: 10321 | C9: 3793 | D9: =B9+C9 -> 14114 | E9: =C9/D9 -> 0.26874026 | G9: =$D9*B$10/$D$10 -> 11264.408 | H9: =$D9*C$10/$D$10 -> 2849.5923 | J9: =(B9-G9)^2/G9 -> 79.011522 | K9: =(C9-H9)^2/H9 -> 312.33169
A10: Total | B10: =SUM(B7:B9) -> 88207 | C10: =SUM(C7:C9) -> 22314 | D10: =SUM(D7:D9) -> 110521 | E10: =C10/D10 -> 0.20189828 | G10: =SUM(G7:G9) -> 88207 | H10: =SUM(H7:H9) -> 22314 | J10: =SUM(J7:J9) -> 91.300818 | K10: =SUM(K7:K9) -> 360.91114
A12: Test summary
A13: Measure | B13: Value | C13: Criterion | D13: Met?
A14: Chi-square (χ²) | B14: =SUM(J7:K9) -> 452.21196 | C14: > critical value | D14: =IF(B14>B16,"Yes","No") -> Yes
A15: Degrees of freedom | B15: =(3-1)*(2-1) -> 2 | C15: (r − 1)(c − 1) | D15: —
A16: Critical value (α = 0.05) | B16: =CHIINV(0.05,B15) -> 5.9914645 | D16: —
A17: p-value | B17: =CHITEST(B7:C9,G7:H9) -> 6.3594642e-99 | C17: < 0.05 | D17: =IF(B17<0.05,"Yes","No") -> Yes
A18: Cramér's V | B18: =SQRT(B14/D10) -> 0.063965915 | C18: see Method | D18: —
A19: Rate difference | B19: =(MAX(E7:E9)-MIN(E7:E9))*100 -> 8.0254584 | C19: 3 | D19: =IF(ABS(B19)>=C19,"Yes","No") -> Yes
A20: Verdict | B20: =IF(AND(B17<0.05,D19="Yes"),IF(B18<0.05,"Confirmed (weak)","Confirmed"),"Rejected") -> Confirmed
A22: Reading
A23: Patients with a prior no-show miss 26.9% of the time, 8.0 p.p. more than returning patients who never missed. About 87% of χ² comes from this group. First-time patients (19.4%) look like those who never missed. History only covers April 29 – June 8, 2016.

Sheet H4.1_Neighborhoods
A1: H4.1 · Neighborhoods above average | L1: ← Back to Overview
A2: Hypothesis: Some neighborhoods have no-show rates at least 3 p.p. above the overall average.
A3: Chi-square 69 × 2 · Only neighborhoods with ≥ 200 appointments (small groups give unstable rates) · Neighborhood = where the patient lives
A5: Observed (sorted by no-show rate) | I5: Expected | L5: Contribution
A6: Neighborhood | B6: No | C6: Yes | D6: Total | E6: No-show rate | F6: Diff vs average | G6: ≥ 3 p.p. above? | I6: Expected No | J6: Expected Yes | L6: Contribution No | M6: Contribution Yes
A7: Santos Dumont | B7: 907 | C7: 369 | D7: =B7+C7 -> 1276 | E7: =C7/D7 -> 0.28918495 | F7: =(E7-$E$76)*100 -> 8.7294801 | G7: =IF(F7>=$C$85,"Above","") -> Above | I7: =$D7*B$76/$D$76 -> 1018.3882 | J7: =$D7*C$76/$D$76 -> 257.61183 | L7: =(B7-I7)^2/I7 -> 12.183295 | M7: =(C7-J7)^2/J7 -> 48.162863
A8: Santa Cecília | B8: 325 | C8: 123 | D8: =B8+C8 -> 448 | E8: =C8/D8 -> 0.27455357 | F8: =(E8-$E$76)*100 -> 7.2663419 | G8: =IF(F8>=$C$85,"Above","") -> Above | I8: =$D8*B$76/$D$76 -> 357.55321 | J8: =$D8*C$76/$D$76 -> 90.446788 | L8: =(B8-I8)^2/I8 -> 2.9637871 | M8: =(C8-J8)^2/J8 -> 11.716409
A9: Santa Clara | B9: 372 | C9: 134 | D9: =B9+C9 -> 506 | E9: =C9/D9 -> 0.26482213 | F9: =(E9-$E$76)*100 -> 6.2931982 | G9: =IF(F9>=$C$85,"Above","") -> Above | I9: =$D9*B$76/$D$76 -> 403.84358 | J9: =$D9*C$76/$D$76 -> 102.15642 | L9: =(B9-I9)^2/I9 -> 2.5109073 | M9: =(C9-J9)^2/J9 -> 9.9260899
A10: Itararé | B10: 2591 | C10: 923 | D10: =B10+C10 -> 3514 | E10: =C10/D10 -> 0.26266363 | F10: =(E10-$E$76)*100 -> 6.0773479 | G10: =IF(F10>=$C$85,"Above","") -> Above | I10: =$D10*B$76/$D$76 -> 2804.558 | J10: =$D10*C$76/$D$76 -> 709.44199 | L10: =(B10-I10)^2/I10 -> 16.26175 | M10: =(C10-J10)^2/J10 -> 64.285766
A11: Jesus De Nazareth | B11: 2157 | C11: 696 | D11: =B11+C11 -> 2853 | E11: =C11/D11 -> 0.24395373 | F11: =(E11-$E$76)*100 -> 4.2063581 | G11: =IF(F11>=$C$85,"Above","") -> Above | I11: =$D11*B$76/$D$76 -> 2277.0074 | J11: =$D11*C$76/$D$76 -> 575.9926 | L11: =(B11-I11)^2/I11 -> 6.3248697 | M11: =(C11-J11)^2/J11 -> 25.003403
A12: Ilha Do Príncipe | B12: 1734 | C12: 532 | D12: =B12+C12 -> 2266 | E12: =C12/D12 -> 0.23477493 | F12: =(E12-$E$76)*100 -> 3.2884782 | G12: =IF(F12>=$C$85,"Above","") -> Above | I12: =$D12*B$76/$D$76 -> 1808.5169 | J12: =$D12*C$76/$D$76 -> 457.48308 | L12: =(B12-I12)^2/I12 -> 3.0703449 | M12: =(C12-J12)^2/J12 -> 12.137652
A13: Caratoíra | B13: 1974 | C13: 591 | D13: =B13+C13 -> 2565 | E13: =C13/D13 -> 0.23040936 | F13: =(E13-$E$76)*100 -> 2.8519205 | G13: =IF(F13>=$C$85,"Above","") | I13: =$D13*B$76/$D$76 -> 2047.1518 | J13: =$D13*C$76/$D$76 -> 517.84824 | L13: =(B13-I13)^2/I13 -> 2.6139635 | M13: =(C13-J13)^2/J13 -> 10.333491
A14: Andorinhas | B14: 1741 | C14: 521 | D14: =B14+C14 -> 2262 | E14: =C14/D14 -> 0.23032714 | F14: =(E14-$E$76)*100 -> 2.8436992 | G14: =IF(F14>=$C$85,"Above","") | I14: =$D14*B$76/$D$76 -> 1805.3245 | J14: =$D14*C$76/$D$76 -> 456.67552 | L14: =(B14-I14)^2/I14 -> 2.2919083 | M14: =(C14-J14)^2/J14 -> 9.0603459
A15: Praia Do Suá | B15: 994 | C15: 294 | D15: =B15+C15 -> 1288 | E15: =C15/D15 -> 0.22826087 | F15: =(E15-$E$76)*100 -> 2.6370718 | G15: =IF(F15>=$C$85,"Above","") | I15: =$D15*B$76/$D$76 -> 1027.9655 | J15: =$D15*C$76/$D$76 -> 260.03452 | L15: =(B15-I15)^2/I15 -> 1.1222693 | M15: =(C15-J15)^2/J15 -> 4.4365422
A16: Gurigica | B16: 1562 | C16: 456 | D16: =B16+C16 -> 2018 | E16: =C16/D16 -> 0.2259663 | F16: =(E16-$E$76)*100 -> 2.4076151 | G16: =IF(F16>=$C$85,"Above","") | I16: =$D16*B$76/$D$76 -> 1610.5857 | J16: =$D16*C$76/$D$76 -> 407.41433 | L16: =(B16-I16)^2/I16 -> 1.4656579 | M16: =(C16-J16)^2/J16 -> 5.7940222
A17: Bento Ferreira | B17: 665 | C17: 193 | D17: =B17+C17 -> 858 | E17: =C17/D17 -> 0.22494172 | F17: =(E17-$E$76)*100 -> 2.3051573 | G17: =IF(F17>=$C$85,"Above","") | I17: =$D17*B$76/$D$76 -> 684.77825 | J17: =$D17*C$76/$D$76 -> 173.22175 | L17: =(B17-I17)^2/I17 -> 0.57124939 | M17: =(C17-J17)^2/J17 -> 2.2582566
A18: Parque Moscoso | B18: 623 | C18: 179 | D18: =B18+C18 -> 802 | E18: =C18/D18 -> 0.22319202 | F18: =(E18-$E$76)*100 -> 2.1301868 | G18: =IF(F18>=$C$85,"Above","") | I18: =$D18*B$76/$D$76 -> 640.0841 | J18: =$D18*C$76/$D$76 -> 161.9159 | L18: =(B18-I18)^2/I18 -> 0.45598134 | M18: =(C18-J18)^2/J18 -> 1.8025802
... A75: Mário Cypreste | B75: 317 | C75: 54 | D75: =B75+C75 -> 371 | E75: =C75/D75 -> 0.14555256 | F75: =(E75-$E$76)*100 -> -5.6337591 | G75: =IF(F75>=$C$85,"Above","") | I75: =$D75*B$76/$D$76 -> 296.09875 | J75: =$D75*C$76/$D$76 -> 74.901246 | L75: =(B75-I75)^2/I75 -> 1.4753932 | M75: =(C75-J75)^2/J75 -> 5.8325078
A76: Total | B76: =SUM(B7:B75) -> 87405 | C76: =SUM(C7:C75) -> 22110 | D76: =SUM(D7:D75) -> 109515 | E76: =C76/D76 -> 0.20189015 | I76: =SUM(I7:I75) -> 87405 | J76: =SUM(J7:J75) -> 22110 | L76: =SUM(L7:L75) -> 96.639345 | M76: =SUM(M7:M75) -> 382.03356
A78: Test summary
A79: Measure | B79: Value | C79: Criterion | D79: Met?
A80: Chi-square (χ²) | B80: =SUM(L7:M75) -> 478.6729 | C80: > critical value | D80: =IF(B80>B82,"Yes","No") -> Yes
A81: Degrees of freedom | B81: =(69-1)*(2-1) -> 68 | C81: (r − 1)(c − 1) | D81: —
A82: Critical value (α = 0.05) | B82: =CHIINV(0.05,B81) -> 88.250164 | D82: —
A83: p-value | B83: =CHITEST(B7:C75,I7:J75) -> 4.9001162e-63 | C83: < 0.05 | D83: =IF(B83<0.05,"Yes","No") -> Yes
A84: Cramér's V | B84: =SQRT(B80/D76) -> 0.066112353 | C84: see Method | D84: —
A85: Neighborhoods ≥ 3 p.p. above average | B85: =COUNTIF(G7:G75,"Above") -> 6 | C85: 3 | D85: =IF(B85>=1,"Yes","No") -> Yes
A86: Their share of appointments | B86: =SUMIF(G7:G75,"Above",D7:D75)/D76 -> 0.099191892 | D86: —
A87: Their share of no-shows | B87: =SUMIF(G7:G75,"Above",C7:C75)/C76 -> 0.12559928 | D87: —
A88: No-shows avoided if they matched the average | B88: =SUMIF(G7:G75,"Above",C7:C75)-SUMIF(G7:G75,"Above",D7:D75)*E76 -> 583.86728 | D88: —
A90: Verdict | B90: =IF(AND(D83="Yes",D85="Yes"),"Confirmed (limited impact)","Rejected") -> Confirmed (limited impact)
A92: Reading
A93: Six neighborhoods miss at least 3 p.p. more than average, led by Santos Dumont (28.9%) and Itararé (26.3%). Together they hold ~10% of appointments and ~13% of no-shows, so neighborhood-specific action has limited impact. With 69 neighborhoods some differences arise by chance; the most solid are the large ones (Itararé, Santos Dumont, Jesus de Nazareth).
A95: Excluded: 12 neighborhoods with < 200 appointments (1,006 appointments)
A96: Neighborhood | B96: No | C96: Yes | D96: Total
A97: Santa Helena | B97: 141 | C97: 37 | D97: =B97+C97 -> 178
A98: Horto | B98: 133 | C98: 42 | D98: =B98+C98 -> 175
A99: Universitário | B99: 120 | C99: 32 | D99: =B99+C99 -> 152
A100: Segurança Do Lar | B100: 117 | C100: 28 | D100: =B100+C100 -> 145
A101: Nazareth | B101: 106 | C101: 29 | D101: =B101+C101 -> 135
...

Sheet H4.2_Neighborhoods_Ctrl
A1: H4.2 · Neighborhood gap within the same lead-time group | L1: ← Back to Overview
A2: Hypothesis: The six above-average neighborhoods still miss more after controlling for lead time.
A3: Rate comparison within each lead-time group (6 neighborhoods from H4.1 vs all others)
A5: Observed counts and rates by lead-time group
A6: Lead time group | B6: No (other) | C6: Yes (other) | D6: No (6 neigh.) | E6: Yes (6 neigh.) | F6: Rate other | G6: Rate 6 neigh. | H6: Difference
A7: Same day | B7: 33362 | C7: 1583 | D7: 3408 | E7: 209 | F7: =C7/(B7+C7) -> 0.045299757 | G7: =E7/(D7+E7) -> 0.057782693 | H7: =(G7-F7)*100 -> 1.2482936
A8: 1–3 days | B8: 10356 | C8: 3018 | D8: 960 | E8: 341 | F8: =C8/(B8+C8) -> 0.22566173 | G8: =E8/(D8+E8) -> 0.26210607 | H8: =(G8-F8)*100 -> 3.6444341
A9: 4–7 days | B9: 11966 | C9: 3939 | D9: 1131 | E9: 474 | F9: =C9/(B9+C9) -> 0.24765797 | G9: =E9/(D9+E9) -> 0.2953271 | H9: =(G9-F9)*100 -> 4.7669134
A10: 8–15 days | B10: 8530 | C10: 3666 | D10: 832 | E10: 500 | F10: =C10/(B10+C10) -> 0.30059036 | G10: =E10/(D10+E10) -> 0.37537538 | H10: =(G10-F10)*100 -> 7.4785018
A11: 16–30 days | B11: 9544 | C11: 4280 | D11: 1165 | E11: 879 | F11: =C11/(B11+C11) -> 0.30960648 | G11: =E11/(D11+E11) -> 0.43003914 | H11: =(G11-F11)*100 -> 12.043266
A12: 31+ days | B12: 6363 | C12: 3051 | D12: 590 | E12: 374 | F12: =C12/(B12+C12) -> 0.32409178 | G12: =E12/(D12+E12) -> 0.3879668 | H12: =(G12-F12)*100 -> 6.3875027
A14: Test summary
A15: Measure | B15: Value | C15: Criterion | D15: Met?
A16: Groups with a positive gap | B16: =COUNTIF(H7:H12,">0") -> 6 | C16: All groups | D16: =IF(B16=6,"Yes","No") -> Yes
A17: Groups with gap ≥ 3 p.p. | B17: =COUNTIF(H7:H12,">="&C17) -> 5 | C17: 3 | D17: =IF(B17>=4,"Yes","No") -> Yes
A18: Largest gap | B18: =MAX(H7:H12) -> 12.043266 | D18: —
A20: Verdict | B20: =IF(AND(D16="Yes",D17="Yes"),"Confirmed","Rejected") -> Confirmed
A22: Reading
A23: The gap is positive in every lead-time group and grows with lead time, from +1.2 p.p. (same day) to +12.0 p.p. (16–30 days). Both groups have a similar lead-time mix, so lead time does not explain the neighborhood effect. Neighborhood may stand for income, distance or transport, which the data cannot separate.
